<?xml version="1.0"?>
<robot name="SingleMotorBot">

  <material name="blue">
    <color rgba="0 0 0.8 1"/>
  </material>

  <material name="white">
    <color rgba="1 1 1 1"/>
  </material>


  <link name="stationary_base_link">
    <visual>
      <geometry>
        <cylinder length="0.6" radius="0.2"/>
      </geometry>
      <material name="blue"/>
    </visual>
  </link>

  <joint name="rotating_joint_1" type="continuous">
    <parent link="stationary_base_link"/>
    <child link="spinning_box"/>
    <axis xyz="0 0 1"/>
    <origin xyz="0 0 0.3"/>
  </joint>

  <link name="spinning_box">
    <visual>
      <geometry>
        <box size="0.2 0.2 0.2"/>
      </geometry>
      <material name="white"/>
    </visual>
  </link>

</robot>
